Description of exception thrown :
Traceback (most recent call last):
  File "/users/geoff/work/master/Testing/TextTest/testmodel.py", line 694, in __init__
    exec importCommand
  File "<string>", line 1, in ?
  File "/users/geoff/texttesttmp/texttestgeoff22Sep111443/TestSelf/ErrorHandling/ConfigBadImport/customconfig.py", line 1, in ?
    import svsdsvgdf
ImportError: No module named svsdsvgdf
Could not use application app - config_module customconfig contained errors and could not be imported
