Description of exception thrown :
Traceback (most recent call last):
  File "/users/geoff/work/master/Testing/TextTest/lib/testmodel.py", line 929, in makeConfigObject
    exec importCommand
  File "<string>", line 1, in ?
  File "/users/geoff/texttesttmp/texttest.04Jun171551/TestSelf/ErrorHandling/Console/ConfigBadImport/customconfig.py", line 1, in ?
    import svsdsvgdf
ImportError: No module named svsdsvgdf
Could not use application 'app' - config_module customconfig contained errors and could not be imported
