Description of exception thrown :
Traceback (most recent call last):
  File "/users/geoff/work/master/Testing/TextTest/lib/testmodel.py", line 1207, in makeConfigObject
    return plugins.importAndCall(moduleName, "getConfig", self.inputOptions)
  File "/users/geoff/work/master/Testing/TextTest/lib/plugins.py", line 140, in importAndCall
    exec command
  File "<string>", line 1, in ?
  File "/carm/proj/texttest-tmp/geoff/texttest.11Jul141027.29844/texttest/TestSelf/ErrorHandling/Console/ConfigBadImport/customconfig.py", line 1, in ?
    import svsdsvgdf
ImportError: No module named svsdsvgdf
Could not use application 'app' - config_module customconfig contained errors and could not be imported
