Description of exception thrown :
Traceback (most recent call last):
  File "/users/geoff/work/master/Testing/TextTest/texttest.py", line 402, in __init__
    exec importCommand
  File "<string>", line 1, in ?
  File "/users/geoff/texttesttmp/texttestgeoff23Jan14:18:46/TestSelf/BadConfig/wibble.py", line 23, in ?
    sdvdsd
NameError: name 'sdvdsd' is not defined
