Description of exception thrown :
Traceback (most recent call last):
  File "/users/geoff/work/master/Testing/TextTest/testmodel.py", line 693, in __init__
    exec importCommand
  File "<string>", line 1, in ?
  File "/users/geoff/texttesttmp/texttestgeoff22Sep111756/TestSelf/ErrorHandling/BadConfig/customconfig.py", line 1, in ?
    svsdsvgdf
NameError: name 'svsdsvgdf' is not defined
Could not use application app - config_module customconfig contained errors and could not be imported
