Description of exception thrown :
Traceback (most recent call last):
  File "/users/geoff/work/master/Testing/TextTest/engine.py", line 33, in handleExceptions
    return method(*args)
  File "/users/geoff/work/master/Testing/TextTest/testmodel.py", line 392, in callAction
    return action(self)
  File "/users/geoff/work/master/Testing/Automatic/texttest/error_config_modules/slaveerr.py", line 18, in __call__
    wibble
NameError: global name 'wibble' is not defined
