Description of exception thrown :
Traceback (most recent call last):
  File "/users/geoff/work/master/Testing/TextTest/lib/default/actionrunner.py", line 228, in handleExceptions
    method(*args)
  File "/carm/proj/texttest-tmp/geoff/texttest.27Aug141259.15758/texttest.lsf/QueueSystems/ErrorHandling/Console/SlaveCrash/customconfig.py", line 18, in __call__
    wibble
NameError: global name 'wibble' is not defined
