Using Application HELLO
WARNING: Caught exception while running HELLO test-case Test changing state to UNRUNNABLE :
Traceback (most recent call last):
  File "/home/geoff/code/texttest/texttestlib/default/actionrunner.py", line 295, in handleExceptions
    method(*args)
  File "/home/geoff/.texttest/tmp/texttest.sge.30Jul163927.10681/texttest.sge/QueueSystems/ErrorHandling/Console/SlaveCrash/customconfig.py", line 18, in __call__
    wibble
NameError: name 'wibble' is not defined
