Description of exception thrown :
Traceback (most recent call last):
  File "/carm/master/Testing/TextTest/testmodel.py", line 655, in __call__
    return self.targetCall(*args)
  File "/carm/master/Testing/TextTest/default.py", line 186, in getFilterFilePath
    dirToUse = filterDirs[0]
IndexError: list index out of range
Traceback (most recent call last):
  File "/carm/master/Testing/TextTest/texttestgui.py", line 1040, in runInteractive
    self._runInteractive(action)
  File "/carm/master/Testing/TextTest/texttestgui.py", line 1043, in _runInteractive
    action.perform()
  File "/carm/master/Testing/TextTest/guiplugins.py", line 158, in perform
    self.performOnCurrent()
  File "/carm/master/Testing/TextTest/guiplugins.py", line 847, in performOnCurrent
    fileName = self.getFileName()
  File "/carm/master/Testing/TextTest/guiplugins.py", line 836, in getFileName
    return app.configObject.getFilterFilePath(app, localName, True)
  File "/carm/master/Testing/TextTest/testmodel.py", line 660, in __call__
    self.raiseException()
  File "/carm/master/Testing/TextTest/testmodel.py", line 664, in raiseException
    raise BadConfigError, message
testmodel.BadConfigError: Exception thrown by 'studio' configuration, while requesting 'getFilterFilePath'
