Description of exception thrown :
Traceback (most recent call last):
  File "/carm/master/Testing/TextTest/texttest.py", line 1265, in setUpApplications
    action.setUpApplication(self.testSuite.app)
  File "/carm/master/Testing/TextTest/batch.py", line 334, in setUpApplication
    app.addConfigEntry("collection", self.getCollectionSetting(), "batch_use_collection")
  File "/carm/master/Testing/TextTest/texttest.py", line 843, in addConfigEntry
    self.configDir.addEntry(key, value, sectionName)
  File "/carm/master/Testing/TextTest/texttest.py", line 1089, in addEntry
    self.currDict = self[sectionName]
  File "/carm/master/Testing/PyUseCase/ndict.py", line 57, in __getitem__
    return self.dict[key]
KeyError: batch_use_collection
Error in set-up of application DIP - exceptions.KeyError: batch_use_collection
